<?xml version="1.0"?>
<robot xmlns:xacro="http://www.ros.org/wiki/xacro">

    <xacro:property name="base_length" value="0.4" />
    <xacro:property name="base_width" value="0.4" />
    <xacro:property name="base_height" value="0.1" />
    <xacro:property name="wheel_radius" value="0.053" />
    <xacro:property name="wheel_length" value="0.05" />
    
    

    <link name="${robot_prefix}base_footprint" />
    <link name="${robot_prefix}base_link">
        <visual>
            <geometry>
                <mesh filename="file://$(find hey_agv_new)/urdf/agv_base.dae"/>
            </geometry>
            <origin xyz="0 0 0" rpy="0 0 1.5708" />
            <material name="blue" />
        </visual>
        <xacro:box_inertia m="18.0" l="0.462" w="0.436" h="0.142" xyz="0 0 0.071" rpy="1.5708 0 0" />
        <collision>
            <geometry>
                <mesh filename="file://$(find hey_agv_new)/urdf/agv_base.dae"/>
            </geometry>
             <origin xyz="0 0 0" rpy="0 0 1.5708" />
        </collision>
    </link>

    <joint name="${robot_prefix}base_footprint_joint" type="fixed">
        <parent link="${robot_prefix}base_link" />
        <child link="${robot_prefix}base_footprint" />
        <origin xyz="0 0 -0.071" rpy="0 0 0"/>
    </joint>

    

    <xacro:macro name="wheel_link" params="prefix">
        <link name="${robot_prefix}${prefix}_wheel_link">
            <visual>
                <geometry>
                    <cylinder radius="${wheel_radius}" length="${wheel_length}" />
                </geometry>
                <origin xyz="0 0 0" rpy="${pi / 2.0} 0 0" />
                <material name="red" />
            </visual>
            <collision>
            <geometry>
                    <cylinder radius="${wheel_radius}" length="${wheel_length}" />
            </geometry>
            <origin xyz="0 0 0" rpy="${pi / 2.0} 0 0" />
            </collision>
            <xacro:cylinder_inertia m="0.5" r="${wheel_radius}" l="${2*wheel_length}" xyz="0 0 0" rpy="${pi / 2.0} 0 0" />
        </link>
    </xacro:macro>

    <xacro:wheel_link prefix="right" />
    <xacro:wheel_link prefix="left" />

    <joint name="${robot_prefix}base_left_wheel_joint" type="continuous">
        <parent link="${robot_prefix}base_link" />
        <child link="${robot_prefix}left_wheel_link" />
        <origin xyz="0 0.183 0.041" rpy="0 0 0" />
        <axis xyz="0 1 0" />
    </joint>

    <joint name="${robot_prefix}base_right_wheel_joint" type="continuous">
        <parent link="${robot_prefix}base_link" />
        <child link="${robot_prefix}right_wheel_link" />
        <origin xyz="0 -0.183 0.041" rpy="0 0 0" />
        <axis xyz="0 1 0" />
    </joint>

    <link name="${robot_prefix}lidar_right">
        <visual>
            <geometry>
                <cylinder radius="0.03" length="0.015" />
            </geometry>
            <origin xyz="0 0 0" rpy="0 0 0" />
            <material name="white" />
        </visual>
        <collision>
            <geometry>
                <cylinder radius="0.03" length="0.015" />
            </geometry>
            <origin xyz="0 0 0" rpy="0 0 0" />
        </collision>
            
    </link>

    

    <joint name="${robot_prefix}lidar_right_base_joint" type="fixed">
        <parent link="${robot_prefix}base_link" />
        <child link="${robot_prefix}lidar_right" />
        <origin xyz="0.115 -0.16789 0.12" rpy="0 0 0"/>
    </joint>

    <link name="${robot_prefix}lidar_left">
        <visual>
            <geometry>
                <cylinder radius="0.03" length="0.015" />
            </geometry>
            <origin xyz="0 0 0" rpy="0 0 0" />
            <material name="white" />
        </visual>
        <collision>
            <geometry>
                <cylinder radius="0.03" length="0.015" />
            </geometry>
            <origin xyz="0 0 0" rpy="0 0 0" />
        </collision>
            
    </link>

    <joint name="${robot_prefix}lidar_left_base_joint" type="fixed">
        <parent link="${robot_prefix}base_link" />
        <child link="${robot_prefix}lidar_left" />
        <origin xyz="-0.115 0.16789 0.12" rpy="0 0 3.14"/>
    </joint>


    <!-- make a square lift -->
    <link name="${robot_prefix}lift_link">
        <visual>
            <geometry>
                <box size="0.184 0.306 0.1" />
            </geometry>
            <origin xyz="0 0 0" rpy="0 0 0" />
            <material name="silver" />
        </visual>
        <collision>
            <geometry>
                <box size="0.184 0.306 0.1" />
            </geometry>
             <origin xyz="0 0 0" rpy="0 0 0" />
        </collision>
        <xacro:box_inertia m="6.0" l="0.306" w="0.184" h="0.1" xyz="0 0 0" rpy="1.5708 0 0" />
    </link>

    <joint name="${robot_prefix}lift_base_joint" type="prismatic">
        <parent link="${robot_prefix}base_link" />
        <child link="${robot_prefix}lift_link" />
        <origin xyz="0 0 0.134" rpy="0 0 1.5708"/>
        <limit lower="0" upper="0.06" effort="100000.0" velocity="1.0"/>
        <axis xyz="0 0 1" />
    </joint>


    <!-- servo motor right-->
    <link name="${robot_prefix}lift_servo_motor_left_link">
        <visual>
            <geometry>
                <box size="0.04 0.02 0.005" />
            </geometry>
            <origin xyz="0 0 0" rpy="0 0 0" />
            <material name="blue" />
        </visual>
        <collision>
            <geometry>
                <box size="0.04 0.02 0.005" />
            </geometry>
             <origin xyz="0 0 0" rpy="0 0 0" />
        </collision>
        <xacro:box_inertia m="0.1" l="0.04" w="0.02" h="0.005" xyz="0 0 0" rpy="1.5708 0 1.5708" />
    </link>

    <joint name="${robot_prefix}lift_servo_motor_left_joint" type="revolute">
        <parent link="${robot_prefix}lift_link" />
        <child link="${robot_prefix}lift_servo_motor_left_link" />
        <origin xyz="-0.0525 -0.07 0.0567" rpy="0 0 0"/>
        <axis xyz="0 0 1" />
        <limit lower="0.0" upper="1.57" effort="1.0" velocity="1.0"/>
    </joint>



    <!-- servo motor left -->
    <link name="${robot_prefix}lift_servo_motor_right_link">
        <visual>
            <geometry>
                <box size="0.04 0.02 0.005" />
            </geometry>
            <origin xyz="0 0 0" rpy="0 0 0" />
            <material name="blue" />
        </visual>
        <collision>
            <geometry>
                <box size="0.04 0.02 0.005" />
            </geometry>
             <origin xyz="0 0 0" rpy="0 0 0" />
        </collision>
        <xacro:box_inertia m="0.1" l="0.04" w="0.02" h="0.005" xyz="0 0 0" rpy="1.5708 0 1.5708" />
    </link>

    <joint name="${robot_prefix}lift_servo_motor_right_joint" type="revolute">
        <parent link="${robot_prefix}lift_link" />
        <child link="${robot_prefix}lift_servo_motor_right_link" />
        <origin xyz="0.0525 0.07 0.0567" rpy="0 0 0"/>
        <axis xyz="0 0 1" />
        <limit lower="0.0" upper="1.57" effort="10.0" velocity="1.0"/>
    </joint>

    <!-- Caster wheel macro -->
    <xacro:macro name="caster_wheel" params="prefix">
        <link name="${robot_prefix}${prefix}_caster_wheel">
            <visual>
                <geometry>
                    <sphere radius="0.0119" />
                </geometry>
                <origin xyz="0 0 0" rpy="0 0 0" />
                <material name="silver" />
            </visual>
            <collision>
                <geometry>
                    <sphere radius="0.0119" />
                </geometry>
                <origin xyz="0 0 0" rpy="0 0 0" />
            </collision>
            <xacro:sphere_inertia m="0.1" r="0.012" xyz="0 0 0" rpy="0 0 0" />
        </link>
    </xacro:macro>

    <!-- Create 4 caster wheels -->
    <xacro:caster_wheel prefix="front_right"/>
    <xacro:caster_wheel prefix="front_left"/>
    <xacro:caster_wheel prefix="rear_right"/>
    <xacro:caster_wheel prefix="rear_left"/>

    <!-- Add appropriate joints with correct positions -->
    <joint name="${robot_prefix}front_right_caster_joint" type="fixed">
        <parent link="${robot_prefix}base_link"/>
        <child link="${robot_prefix}front_right_caster_wheel"/>
        <origin xyz="0.17 -0.17 0.0" rpy="0 0 0"/>
    </joint>

    <joint name="${robot_prefix}front_left_caster_joint" type="fixed">
        <parent link="${robot_prefix}base_link"/>
        <child link="${robot_prefix}front_left_caster_wheel"/>
        <origin xyz="0.17 0.17 0.0" rpy="0 0 0"/>
    </joint>

    <joint name="${robot_prefix}rear_right_caster_joint" type="fixed">
        <parent link="${robot_prefix}base_link"/>
        <child link="${robot_prefix}rear_right_caster_wheel"/>
        <origin xyz="-0.17 -0.17 0.0" rpy="0 0 0"/>
    </joint>

    <joint name="${robot_prefix}rear_left_caster_joint" type="fixed">
        <parent link="${robot_prefix}base_link"/>
        <child link="${robot_prefix}rear_left_caster_wheel"/>
        <origin xyz="-0.17 0.17 0.0" rpy="0 0 0"/>
    </joint>



    <link name="${robot_prefix}camera">
        <visual>
            <geometry>
                <box size="0.01 0.06 0.02" />
            </geometry>
            <origin xyz="0 0 0" rpy="0 0 0" />
            <material name="white" />
        </visual>
        <collision>
            <geometry>
                <box size="0.01 0.06 0.02" />
            </geometry>
             <origin xyz="0 0 0" rpy="0 0 0" />
        </collision>
        <xacro:box_inertia m="0.03" l="0.02" w="0.06" h="0.02" xyz="0 0 0" rpy="0 0 0" />
    </link>


    <joint name="${robot_prefix}camera_base_joint_optical" type="fixed">
        <parent link="${robot_prefix}camera" />
        <child link="${robot_prefix}camera_optical_link" />
        <!-- <origin xyz="0.237 0 0.03" rpy="0 -0.1 0"/>   it was 0.03 -->
        <origin xyz="0 0 0" rpy="-1.5708 0 -1.5708"/> 
    </joint>

    <link name="${robot_prefix}camera_optical_link" ></link>

    <!-- for optical correctness -->
    <joint name="${robot_prefix}camera_base_joint" type="fixed">
        <parent link="${robot_prefix}base_link" />
        <child link="${robot_prefix}camera" />
        <!-- <origin xyz="0.237 0 0.03" rpy="0 -0.1 0"/>   it was 0.03 -->
        <origin xyz="0.25 0 0.03" rpy="0 -0.1 0"/> 
    </joint>

</robot>